<?xml version="1.0" ?>
<robot name="prismatic_joint_robot">
  <link name="base_link">
    <visual>
      <geometry>
        <box size="0.1 0.1 0.1" />
      </geometry>
    </visual>
  </link>

  <link name="end_link">
    <visual>
      <geometry>
        <box size="0.1 0.1 0.1" />
      </geometry>
    </visual>
  </link>
  
  <joint name="prismatic_joint" type="prismatic">
    <parent link="base_link" />
    <child link="end_link" />
    <origin xyz="0 0 0" rpy="0 0 0" />
    <axis xyz="1 0 0" />
    <limit lower="-1" upper="1" effort="10" velocity="1" />
  </joint>
</robot><?xml version="1.0" ?>
<robot name="prismatic_joint_robot">
  <link name="base_link">
    <visual>
      <geometry>
        <box size="0.1 0.1 0.1" />
      </geometry>
    </visual>
  </link>

  <link name="end_link">
    <visual>
      <geometry>
        <box size="0.1 0.1 0.1" />
      </geometry>
    </visual>
  </link>
  
  <joint name="prismatic_joint" type="prismatic">
    <parent link="base_link" />
    <child link="end_link" />
    <origin xyz="0 0 0" rpy="0 0 0" />
    <axis xyz="1 0 0" />
    <limit lower="-1" upper="1" effort="10" velocity="1" />
  </joint>
</robot>