<?xml version="1.0"?>
<robot name="pan_tilt">

  <link name="base_link">

    <visual>
        <geometry>
	      <cylinder length="0.01" radius="0.2"/>
       </geometry>
        <origin rpy="0 0 0" xyz="0 0 0"/>
        <material name="yellow">
        <color rgba="1 1 0 1"/>
        </material>
    </visual>

    <collision>
      <geometry>
	    <cylinder length="0.03" radius="0.2"/>
      </geometry>
      <origin rpy="0 0 0" xyz="0 0 0"/>
    </collision>

    <inertial>
	    <mass value="1"/>
	    <inertia ixx="1.0" ixy="0.0" ixz="0.0" iyy="1.0" iyz="0.0" izz="1.0"/>
    </inertial>
  </link>


  <joint name="pan_joint" type="revolute">
    <parent link="base_link"/>
    <child link="pan_link"/>
    <origin xyz="0 0 0.1"/>
    <axis xyz="0 0 1" />
    <limit effort="300" velocity="0.1" lower="-3.14" upper="3.14"/>
    <dynamics damping="50" friction="1"/>
  </joint>


  <link name="pan_link">
    <visual>
      <geometry>
	    <cylinder length="0.4" radius="0.04"/>
      </geometry>
      <origin rpy="0 0 0" xyz="0 0 0.09"/>
      <material name="red">
        <color rgba="0 0 1 1"/>
      </material>
    </visual>


    <collision>
      <geometry>
	    <cylinder length="0.4" radius="0.06"/>
      </geometry>
      <origin rpy="0 0 0" xyz="0 0 0.09"/>
    </collision>

    <inertial>
    	<mass value="1"/>
	    <inertia ixx="1.0" ixy="0.0" ixz="0.0" iyy="1.0" iyz="0.0" izz="1.0"/>
    </inertial>
  </link>


  <joint name="tilt_joint" type="revolute">
    <parent link="pan_link"/>
    <child link="tilt_link"/>
    <origin xyz="0 0 0.2"/>
    <axis xyz="0 1 0" />
    <limit effort="300" velocity="0.1" lower="-4.64" upper="-1.5"/>
    <dynamics damping="50" friction="1"/>
  </joint>


  <link name="tilt_link">
    <visual>
      <geometry>
	      <cylinder length="0.4" radius="0.04"/>
      </geometry>
      <origin rpy="0 1.5 0" xyz="0 0 0"/>
      <material name="green">
        <color rgba="1 0 0 1"/>
      </material>
    </visual>

    <collision>
      <geometry>
	    <cylinder length="0.4" radius="0.06"/>
      </geometry>
      <origin rpy="0 1.5 0" xyz="0 0 0"/>
    </collision>

    <inertial>
	    <mass value="1"/>
    	<inertia ixx="1.0" ixy="0.0" ixz="0.0" iyy="1.0" iyz="0.0" izz="1.0"/>
    </inertial>

  </link>

<link name="gripper_finger_link1">
    <visual>
      <origin xyz="0.04 -0.03 0"/>
      <geometry>
        <box size="0.08 0.01 0.01"/>
      </geometry>
      <material>
    </visual>
    <inertial>
      <mass value="1"/>
      <inertia ixx="1.0" ixy="0.0" ixz="0.0" iyy="0.5" iyz="0.0" izz="1.0"/>
    </inertial>
  </link>
  <gazebo reference="l_gripper_aft_link">
    <material>
  </gazebo>


  <!-- Joint between Wrist roll and finger 2 -->
  <joint name="finger_joint2" type="prismatic">
    <parent link="tilt_link"/>
    <child link="gripper_finger_link2"/>
    <origin xyz="0.0 0 0"/>
    <axis xyz="0 1 0"/>
    <limit effort="1" lower="-0.03" upper="0" velocity="1.0"/>
    <!--    <mimic joint="gripper_finger_joint" multiplier="-1.0" offset="0.0" /> -->
    <dynamics damping="50" friction="1"/>

    
  </joint>






</robot>
